<?xml version="1.0"?>
<robot  xmlns:xacro="http://www.ros.org/wiki/xacro" name="mycobot_280jn" >
	
<xacro:property name="width" value=".2" />

  <link name="base_link">
    <visual>
      <geometry>
        <mesh filename="package://mycobot_description/meshes/mycobot_280/G_base.dae"/>
      </geometry>
      <origin xyz = "0.0 0 -0.032" rpy = "0 0 1.5708"/>
    </visual>
    <collision>
      <geometry>
        <mesh filename="package://mycobot_description/meshes/mycobot_280/G_base.dae"/>
      </geometry>
      <origin xyz = "0.0 0 -0.032" rpy = "0 0 1.5708"/>
    </collision>
  </link>

  <link name="link1">
    <visual>
      <geometry>
       <mesh filename="package://mycobot_description/meshes/mycobot_280/joint1.dae"/>
      </geometry>
    <origin xyz = "0.0 0 0 " rpy = " 0 0 3.14159"/>
    </visual>
    <collision>
      <geometry>
        <mesh filename="package://mycobot_description/meshes/mycobot_280/joint1.dae"/>
      </geometry>
      <origin xyz = "0.0 0 0" rpy = "0 0 3.14159"/>
    </collision>
  </link>

  <link name="link2">
    <visual>
      <geometry>
       <mesh filename="package://mycobot_description/meshes/mycobot_280/joint2.dae"/>
      </geometry>
    <origin xyz = "0.0 0 -0.06096 " rpy = " 0 0 -1.5708"/>
    </visual>
    <collision>
      <geometry>
        <mesh filename="package://mycobot_description/meshes/mycobot_280/joint2.dae"/>
      </geometry>
      <origin xyz = "0.0 0 -0.06096" rpy = "0 0 -1.5708"/>
    </collision>
  </link>


  <link name="link3">
    <visual>
      <geometry>
       
       <mesh filename="package://mycobot_description/meshes/mycobot_280/joint3.dae"/>
      </geometry>
    <origin xyz = "0.0 0 0.03256 " rpy = " 0 -1.5708 0"/>
    </visual>
    <collision>
      <geometry>
        <mesh filename="package://mycobot_description/meshes/mycobot_280/joint3.dae"/>
      </geometry>
      <origin xyz = "0.0 0 0.03256" rpy = "0 -1.5708 0"/>
    </collision>
  </link>


  <link name="link4">
    <visual>
      <geometry>
       <mesh filename="package://mycobot_description/meshes/mycobot_280/joint4.dae"/>
      </geometry>
    <origin xyz = "0.0 0 0.03056 " rpy = " 0 -1.5708 0"/>
    </visual>
    <collision>
      <geometry>
        <mesh filename="package://mycobot_description/meshes/mycobot_280/joint4.dae"/>
      </geometry>
      <origin xyz = "0.0 0 0.03056" rpy = "0 -1.5708 0"/>
    </collision>
  </link>


<link name="link5">
    <visual>
      <geometry>
       <mesh filename="package://mycobot_description/meshes/mycobot_280/joint5.dae"/>
      </geometry>
    <origin xyz = "0.0 0 -0.03356 " rpy = " 0 -1.5708 1.5708"/>
    </visual>
    <collision>
      <geometry>
        <mesh filename="package://mycobot_description/meshes/mycobot_280/joint5.dae"/>
      </geometry>
      <origin xyz = "0.0 0 -0.03356" rpy = "0 -1.5708 1.5708"/>
    </collision>
  </link>


  <link name="link6">
    <visual>
      <geometry>
       <mesh filename="package://mycobot_description/meshes/mycobot_280/joint6.dae"/>
      </geometry>
    <origin xyz = "0 0.00 -0.038 " rpy = " 0 0 0"/>
    </visual>
    <collision>
      <geometry>
        <mesh filename="package://mycobot_description/meshes/mycobot_280/joint6.dae"/>
      </geometry>
      <origin xyz = "0 0.00 -0.038" rpy = "0 0 0"/>
    </collision>
  </link>


  <link name="link6_flange">
    <visual>
      <geometry>
       <mesh filename="package://mycobot_description/meshes/mycobot_280/joint7.dae"/>
      </geometry>
    <origin xyz = "0.0 0 -0.012 " rpy = " 0 0 0"/>
    </visual>
    <collision>
      <geometry>
        <mesh filename="package://mycobot_description/meshes/mycobot_280/joint7.dae"/>
      </geometry>
      <origin xyz = "0.0 0 -0.012" rpy = "0 0 0"/>
    </collision>
  </link>


  <link name="camera_flange">
    <visual>
      <geometry>
       <mesh filename="package://mycobot_description/meshes/mycobot_280/camera_flange.dae"/>
      </geometry>
    <origin xyz = "0.024 -0.008 0.0 " rpy = " 0 3.14159 0"/>
    </visual>
    <collision>
      <geometry>
       <mesh filename="package://mycobot_description/meshes/mycobot_280/camera_flange.dae"/>
      </geometry>
    <origin xyz = "0.024 -0.008 0.0 " rpy = " 0 3.14159 0"/>
    </collision>
  </link>
  
<link name="gripper_base">
    <inertial>
        <origin xyz="0 0 0.0" rpy="0 0 0"/>
        <mass value="0.07"/>
        <inertia
            ixx="0.000010725" ixy="0.0" ixz="0.0"
            iyy="0.000014392" iyz="0.0"
            izz="0.000018517"/>
    </inertial>
    <visual>
        <geometry>
            <mesh filename="package://mycobot_description/meshes/mycobot_280/gripper_base.dae"/>
        </geometry>
        <origin xyz="0.0 0.0 -0.012" rpy="0 0 0"/>
    </visual>
    <collision>
        <geometry>
            <box size="0.065 0.025 0.025"/>
        </geometry>
        <origin xyz="0.0 0.0 0.0" rpy="0 0 0"/>
    </collision>
</link>

<link name="gripper_left1">
    <inertial>
        <origin xyz="0 0 0.0" rpy="0 0 0"/>
        <mass value="0.007"/>
        <inertia
            ixx="1e-6" ixy="0.0" ixz="0.0"
            iyy="1e-6" iyz="0.0"
            izz="1e-6"/>
    </inertial>
    <visual>
        <geometry>
            <mesh filename="package://mycobot_description/meshes/mycobot_280/gripper_left1.dae"/>
        </geometry>
        <origin xyz="0.039 -0.0133 -0.012" rpy="0 0 0"/>
    </visual>
    <collision>
        <geometry>
            <box size="0.013 0.02 0.015"/>
        </geometry>
        <origin xyz="0.013 0.042 -0.010" rpy="0 0 0"/>
    </collision>
</link>

<link name="gripper_left2">
    <inertial>
        <origin xyz="0 0 0.0" rpy="0 0 0"/>
        <mass value="0.007"/>
        <inertia
            ixx="1e-6" ixy="0.0" ixz="0.0"
            iyy="1e-6" iyz="0.0"
            izz="1e-6"/>
    </inertial>
    <visual>
        <geometry>
            <mesh filename="package://mycobot_description/meshes/mycobot_280/gripper_left2.dae"/>
        </geometry>
        <origin xyz="0.005 -0.0195 -0.012" rpy="0 0 0"/>
    </visual>
    <collision>
        <geometry>
            <box size="0.02 0.02 0.02"/>
        </geometry>
        <origin xyz="-0.025 0.0 -0.010" rpy="0 0 0"/>
    </collision>
</link>

<link name="gripper_left3">
    <inertial>
        <origin xyz="0 0 0.0" rpy="0 0 0"/>
        <mass value="0.007"/>
        <inertia
            ixx="1e-6" ixy="0.0" ixz="0.0"
            iyy="1e-6" iyz="0.0"
            izz="1e-6"/>
    </inertial>
    <visual>
        <geometry>
            <mesh filename="package://mycobot_description/meshes/mycobot_280/gripper_left3.dae"/>
        </geometry>
        <origin xyz="0.012 0.0025 -0.012" rpy="0 0 0"/>
    </visual>
    <collision>
        <geometry>
            <box size="0.01 0.01 0.01"/>
        </geometry>
        <origin xyz="-0.014 0.005 0.005" rpy="0 0 0"/>
    </collision>
</link>

<link name="gripper_right1">
    <inertial>
        <origin xyz="0 0 0.0" rpy="0 0 0"/>
        <mass value="0.007"/>
        <inertia
            ixx="1e-6" ixy="0.0" ixz="0.0"
            iyy="1e-6" iyz="0.0"
            izz="1e-6"/>
    </inertial>
    <visual>
        <geometry>
            <mesh filename="package://mycobot_description/meshes/mycobot_280/gripper_right1.dae"/>
        </geometry>
        <origin xyz="-0.039 -0.0133 -0.012" rpy="0 0 0"/>
    </visual>
    <collision>
        <geometry>
            <box size="0.013 0.02 0.015"/>
        </geometry>
        <origin xyz="-0.013 0.042 -0.010" rpy="0 0 0"/>
    </collision>
</link>

<link name="gripper_right2">
    <inertial>
        <origin xyz="0 0 0.0" rpy="0 0 0"/>
        <mass value="0.007"/>
        <inertia
            ixx="1e-6" ixy="0.0" ixz="0.0"
            iyy="1e-6" iyz="0.0"
            izz="1e-6"/>
    </inertial>
    <visual>
        <geometry>
            <mesh filename="package://mycobot_description/meshes/mycobot_280/gripper_right2.dae"/>
        </geometry>
        <origin xyz="-0.005 -0.0195 -0.012" rpy="0 0 0"/>
    </visual>
    <collision>
        <geometry>
            <box size="0.02 0.02 0.02"/>
        </geometry>
        <origin xyz="0.025 0.0 -0.010" rpy="0 0 0"/>
    </collision>
</link>

<link name="gripper_right3">
    <inertial>
        <origin xyz="0 0 0.0" rpy="0 0 0"/>
        <mass value="0.007"/>
        <inertia
            ixx="1e-6" ixy="0.0" ixz="0.0"
            iyy="1e-6" iyz="0.0"
            izz="1e-6"/>
    </inertial>
    <visual>
        <geometry>
            <mesh filename="package://mycobot_description/meshes/mycobot_280/gripper_right3.dae"/>
        </geometry>
        <origin xyz="-0.012 0.0025 -0.012" rpy="0 0 0"/>
    </visual>
    <collision>
        <geometry>
            <box size="0.01 0.01 0.01"/>
        </geometry>
        <origin xyz="0.014 0.005 0.005" rpy="0 0 0"/>
    </collision>
</link>

  <joint name="base_to_joint1" type="fixed">
    <axis xyz="0 0 0"/>
    <limit effort = "1000.0" lower = "-3.14" upper = "3.14159" velocity = "0"/>
    <parent link="base_link"/>
    <child link="link1"/>
    <origin xyz= "0 0 0" rpy = "0 0 0"/>  
  </joint>
  

  <joint name="joint2_to_joint1" type="revolute">
    <axis xyz="0 0 1"/>
    <limit effort = "1000.0" lower = "-2.9321" upper = "2.9321" velocity = "0"/>
    <parent link="link1"/>
    <child link="link2"/>
    <origin xyz= "0 0 0.15756" rpy = "0 0 0"/>  
  </joint>


  <joint name="joint3_to_joint2" type="revolute">
    <axis xyz="0 0 1"/>
    <limit effort = "1000.0" lower = "-2.3562" upper = "2.3562" velocity = "0"/>
    <parent link="link2"/>
    <child link="link3"/>
    <origin xyz= "0 0 -0.001" rpy = "0 1.5708 -1.5708"/>  
  </joint>


  <joint name="joint4_to_joint3" type="revolute">
    <axis xyz=" 0 0 1"/>
    <limit effort = "1000.0" lower = "-2.6179" upper = "2.6179" velocity = "0"/>
    <parent link="link3"/>
    <child link="link4"/>
    <origin xyz= "  -0.1104 0 0   " rpy = "0 0 0"/>  
  </joint>

  <joint name="joint5_to_joint4" type="revolute">
    <axis xyz=" 0 0 1"/>
    <limit effort = "1000.0" lower = "-2.5307" upper = "2.5307" velocity = "0"/>
    <parent link="link4"/>
    <child link="link5"/>
    <origin xyz= "-0.096 0 0.06462" rpy = "0 0 -1.5708"/>  
  </joint>

  <joint name="joint6_to_joint5" type="revolute">
    <axis xyz="0 0 1"/>
    <limit effort = "1000.0" lower = "-2.8797" upper = "2.8797" velocity = "0"/>
    <parent link="link5"/>
    <child link="link6"/>
    <origin xyz= "0 -0.07318 0" rpy = "1.5708 -1.5708 0"/>  
  </joint>

  <joint name="joint6output_to_joint6" type="revolute">
    <axis xyz="0 0 1"/>
    <limit effort = "1000.0" lower = "-3.14" upper = "3.14159" velocity = "0"/>
    <parent link="link6"/>
    <child link="link6_flange"/>
    <origin xyz= "0 0.0456 0" rpy = "-1.5708 0 0"/>  
  </joint>

  <joint name="joint6output_to_camera_flange" type="fixed">
    <parent link="link6_flange"/>
    <child link="camera_flange"/>
    <origin xyz= "0 0 0.01" rpy = "1.579 0 -1.579"/>  
  </joint>

<joint name="cameraflange_to_gripper_base" type="fixed">
    <parent link="camera_flange"/>
    <child link="gripper_base"/>
    <origin xyz="0 0.042 0" rpy="0 -1.579 0"/>
</joint>

<joint name="gripper_controller" type="revolute">
    <axis xyz="0 0 1"/>
    <limit effort="1000.0" lower="-0.7" upper="0.15" velocity="0"/>
    <parent link="gripper_base"/>
    <child link="gripper_left3"/>
    <origin xyz="-0.012 0.005 0" rpy="0 0 0"/> 
</joint>

<joint name="gripper_base_to_gripper_left2" type="revolute">
    <axis xyz="0 0 1"/>
    <limit effort="1000.0" lower="-0.8" upper="0.5" velocity="0"/>
    <parent link="gripper_base"/>
    <child link="gripper_left2"/>
    <origin xyz="-0.005 0.027 0" rpy="0 0 0"/> 
    <mimic joint="gripper_controller" multiplier="1.0" offset="0"/>
</joint>

<joint name="gripper_left3_to_gripper_left1" type="revolute">
    <axis xyz="0 0 1"/>
    <limit effort="1000.0" lower="-0.5" upper="0.5" velocity="0"/>
    <parent link="gripper_left3"/>
    <child link="gripper_left1"/>
    <origin xyz="-0.027 0.016 0" rpy="0 0 0"/> 
    <mimic joint="gripper_controller" multiplier="-1.0" offset="0"/>
</joint>

<joint name="gripper_base_to_gripper_right3" type="revolute">
    <axis xyz="0 0 1"/>
    <limit effort="1000.0" lower="-0.15" upper="0.7" velocity="0"/>
    <parent link="gripper_base"/>
    <child link="gripper_right3"/>
    <origin xyz="0.012 0.005 0" rpy="0 0 0"/> 
    <mimic joint="gripper_controller" multiplier="-1.0" offset="0"/>
</joint>

<joint name="gripper_base_to_gripper_right2" type="revolute">
    <axis xyz="0 0 1"/>
    <limit effort="1000.0" lower="-0.5" upper="0.8" velocity="0"/>
    <parent link="gripper_base"/>
    <child link="gripper_right2"/>
    <origin xyz="0.005 0.027 0" rpy="0 0 0"/> 
    <mimic joint="gripper_controller" multiplier="-1.0" offset="0"/>
</joint>

<joint name="gripper_right3_to_gripper_right1" type="revolute">
    <axis xyz="0 0 1"/>
    <limit effort="1000.0" lower="-0.5" upper="0.5" velocity="0"/>
    <parent link="gripper_right3"/>
    <child link="gripper_right1"/>
    <origin xyz="0.027 0.016 0" rpy="0 0 0"/> 
    <mimic joint="gripper_controller" multiplier="1.0" offset="0"/>
</joint>

</robot>

